import { Body, Controller, Delete, Get, HttpException, HttpStatus, Param, Patch, Post } from '@nestjs/common';
import { createCategoryDto, updateCategoryDto } from 'src/application/dto/category';
import * as useCase from 'src/application/uses-cases/category/index';
import { ParseObjectIdPipe } from 'src/shared/pipes/parse-object-id.pipe';

@Controller('category')
export class CategoryController {

    constructor(
            private createUseCase: useCase.CreateCategoryUseCase,
            private getAllCase: useCase.GetAllCategoryUseCase,
            private getOneCase: useCase.GetOneCategoryUseCase,
            private deleteCase: useCase.DeleteCategoryUseCase,
            private updateCase: useCase.UpdateCategoryUseCase,
        ){}
    
        @Post()
        async create(@Body() dto: createCategoryDto ){
                const result = await this.createUseCase.execute(dto);
        
                if(result.isFailure){
                    if (result.error) {
                        throw new HttpException(result.error.message, HttpStatus.BAD_REQUEST);
                    }
                    // Es buena práctica tener un fallback por si algo inesperado ocurre
                    throw new HttpException('An unknown error occurred', HttpStatus.INTERNAL_SERVER_ERROR);
                }
        
                return {
                    data: result.getValue(),
                    message: 'Category creado.'
                }
        
        }
    
        @Get()
        async getAll() {
            const result = await this.getAllCase.execute();
        
            if(result.isFailure){
                if (result.error) {
                    throw new HttpException(result.error.message, HttpStatus.BAD_REQUEST);
                }
                    // Es buena práctica tener un fallback por si algo inesperado ocurre
                throw new HttpException('An unknown error occurred', HttpStatus.INTERNAL_SERVER_ERROR);
            }
        
            return {
              data: result,
              message: 'Category obtenidos',
            };
        }
    
    
        @Get(':id')
        async findOne(@Param('id', ParseObjectIdPipe) id: string) {
                const result = await this.getOneCase.execute(id);
            
                if(result.isFailure){
                    if (result.error) {
                        throw new HttpException(result.error.message, HttpStatus.BAD_REQUEST);
                    }
                        // Es buena práctica tener un fallback por si algo inesperado ocurre
                    throw new HttpException('An unknown error occurred', HttpStatus.INTERNAL_SERVER_ERROR);
                }
            
                return {
                  data: result,
                  message: 'Category obtenido',
                };
        }
    
    
        @Delete(':id')
        async remove(@Param('id', ParseObjectIdPipe) id: string) {
            const result = await this.deleteCase.execute(id);
          
            if(result.isFailure){
                if (result.error) {
                    throw new HttpException(result.error.message, HttpStatus.BAD_REQUEST);
                }
                    // Es buena práctica tener un fallback por si algo inesperado ocurre
                throw new HttpException('An unknown error occurred', HttpStatus.INTERNAL_SERVER_ERROR);
            }
          
            return {
              data: result,
              message: 'Category eliminado.',
            };
        }
    
        @Patch(':id')
        async update(@Param('id', ParseObjectIdPipe) id:string, @Body() updateCategoryDto: updateCategoryDto){
                const result = await this.updateCase.execute(
                  id,
                  updateCategoryDto,
                );
            
                if(result.isFailure){
                    if (result.error) {
                        throw new HttpException(result.error.message, HttpStatus.BAD_REQUEST);
                    }
                        // Es buena práctica tener un fallback por si algo inesperado ocurre
                    throw new HttpException('An unknown error occurred', HttpStatus.INTERNAL_SERVER_ERROR);
                }
            
                return {
                  data: result,
                  message: 'Category actualizado',
                };
        }

    
}
